Workbook
Name _ACTR_1: '[1]Skill Calcs'!$Q$2
Name _ACTR_1: 'Skill Calcs'!$L$2
Name _ACTR_2: 'Skill Calcs'!$L$3
Name _ACTR_3: 'Skill Calcs'!$L$4
Name _ACTR_4: 'Skill Calcs'!$L$5
Name _ACTR_5: 'Skill Calcs'!$L$6
Name _ACTR_6: 'Skill Calcs'!$L$7
Name _ACTR_7: 'Skill Calcs'!$L$8
Name _ACTR_8: 'Skill Calcs'!$L$9
Name _ACTR_9: 'Skill Calcs'!$L$10
Name _AE_CBulk_1: 'Edge Calcs'!$M$2
Name _AE_CBulk_2: 'Edge Calcs'!$M$3
Name _AE_CBulk_3: 'Edge Calcs'!$M$4
Name _AE_CBulk_4: 'Edge Calcs'!$M$5
Name _AE_CBulk_5: 'Edge Calcs'!$M$6
Name _AE_CBulk_6: 'Edge Calcs'!$M$7
Name _AE_CBulk_7: 'Edge Calcs'!$M$8
Name _AE_CBulk_8: 'Edge Calcs'!$M$9
Name _AE_CBulk_9: 'Edge Calcs'!$M$10
Name _AE_CCost_1: 'Edge Calcs'!$L$2
Name _AE_CCost_2: 'Edge Calcs'!$L$3
Name _AE_CCost_3: 'Edge Calcs'!$L$4
Name _AE_CCost_4: 'Edge Calcs'!$L$5
Name _AE_CCost_5: 'Edge Calcs'!$L$6
Name _AE_CCost_6: 'Edge Calcs'!$L$7
Name _AE_CCost_7: 'Edge Calcs'!$L$8
Name _AE_CCost_8: 'Edge Calcs'!$L$9
Name _AE_CCost_9: 'Edge Calcs'!$L$10
Name _CTR_2: '[1]Skill Calcs'!$Q$3
Name _CTR_3: '[1]Skill Calcs'!$Q$4
Name _CTR_4: '[1]Skill Calcs'!$Q$5
Name _CTR_5: '[1]Skill Calcs'!$Q$6
Name _CTR_6: '[1]Skill Calcs'!$Q$7
Name _CTR_7: '[1]Skill Calcs'!$Q$8
Name _CTR_8: '[1]Skill Calcs'!$Q$9
Name _CTR_9: '[1]Skill Calcs'!$Q$10
Name _Lang_CTR: 'Skill Calcs'!$L$15
Name _OCTR_1: 'Skill Calcs'!$L$11
Name _OCTR_2: 'Skill Calcs'!$L$12
Name _OCTR_3: 'Skill Calcs'!$L$13
Name _OCTR_4: 'Skill Calcs'!$L$14
Name _Sum_Skill_Costs: '[1]Skill Calcs'!$S$11
Name _Sum_Skill_Costs: 'Skill Calcs'!$N$17
Name A_Area_1: Doc!$R$11
Name A_Area_2: Doc!$R$21
Name A_Area_3: Doc!$R$31
Name A_Area_4: Doc!$R$41
Name A_Area_5: Doc!$R$51
Name A_Area_6: Doc!$R$61
Name A_Area_7: Doc!$R$71
Name A_Area_8: Doc!$R$81
Name A_Area_9: Doc!$R$91
Name A_Bolster_1: Doc!$Z$11
Name A_Bolster_2: Doc!$Z$21
Name A_Bolster_3: Doc!$Z$31
Name A_Bolster_4: Doc!$Z$41
Name A_Bolster_5: Doc!$Z$51
Name A_Bolster_6: Doc!$Z$61
Name A_Bolster_7: Doc!$Z$71
Name A_Bolster_8: Doc!$Z$81

Sheet Doc
A1: Name: | G1: Han Jones (Brian) | BJ1: Species: | BR1: Human | DI1: Untold RPG
A5: Active Skills: | AB5: B/M | AH5: SR | AL5: TR | AP5: TN | AU5: BTR | AZ5: BDR | BD5: Wounds & Exertion | BV5: MDR | BZ5: MTR | CF5: Weaknesses | DO5: Cost
A7: Skill | E7: Haggling | AB7: =_xlfn.XLOOKUP(E9,BroadSkills,BroadSkillAspects,"",0,1) -> Mind | AH7: 6 | AL7: =IF(_ACTR_1>0,_ACTR_1,"") -> 2 | AP7: 8 | AU7: 1 | AZ7: 1 | BV7: 2 | BZ7: 2 | CF7: Addict: Vaping (Sc 12, Cm 3, Agitation 1) | DO7: 16
A9: Umb | E9: Influence | CF9: Obsession: Greed (2) | DO9: 8
AH10: blk | AN10: dg | AP10: =P11 -> 0
A11: Edges, etc. | R11: 0 | Z11: 0 | AF11: =_AE_CCost_1 -> 0 | AU11: Endurance | BG11: base | BI11: =3*(AU7+1) -> 6 | BM11: Tenacity | BY11: base | CA11: =3*(BZ7+1) -> 9 | CF11: Wanted: Loan Shark (A:3,F:6,L:3,C:6) | DO11: 18
AM13: init | AP13: =IFERROR(ATR_1-MAX(A_Bulk_1,AR_Bulk),"") -> 2 | CF13: U Traits: Loud Laugh, Disorganized | DO13: 6
E15: Sincere (1) | CF15: Animal Incompetance | DO15: 14
A17: Skill | E17: Persuasion | AB17: =_xlfn.XLOOKUP(E19,BroadSkills,BroadSkillAspects,"",0,1) -> Mind | AH17: 3 | AL17: =IF(_ACTR_2>0,_ACTR_2,"") -> 1 | AP17: 8
A19: Umb | E19: Influence | AU19: Wounds | BD19: Strain | BM19: Strain | BV19: Wounds
AH20: blk | AN20: dg | AP20: =P21 -> 0 | CF20: Strengths | DO20: Cost
A21: Edges, etc. | AF21: =_AE_CCost_2 -> 0 | AU21: ↘ | BV21: ↙
BD22: Resilience | BP22: base | BR22: =2*(ROUNDUP(MAX(AU7,BZ7),0)+1) -> 6 | CF22: Adaptable (Enhance 1: Survival) | DO22: 15
AM23: init | AP23: =IFERROR(ATR_2-MAX(A_Bulk_2,AR_Bulk),"") -> 1
CF24: Sincere (Enhance 1: Influence) | DO24: 22
E25: Sincere (1)
CF26: Resourceful (+1 Tier: Apple:Orange) | DO26: 18
A27: Skill | E27: Deception | AB27: =_xlfn.XLOOKUP(E29,BroadSkills,BroadSkillAspects,"",0,1) -> Mind | AH27: 4 | AL27: =IF(_ACTR_3>0,_ACTR_3,"") -> 1 | AP27: 8 | AU27: ↙ | BV27: ↘
A29: Umb | E29: Influence
AH30: blk | AN30: dg | AP30: =P31 -> 0 | BD30: Wounds | BM30: Strain
A31: Edges, etc. | AF31: =_AE_CCost_3 -> 0
AM33: init | AP33: =IFERROR(ATR_3-MAX(A_Bulk_3,AR_Bulk),"") -> 1 | AU33: Vitality | BG33: base | BI33: =AU7+3 -> 4 | BM33: Sanity | BY33: base | CA33: =BZ7+3 -> 5
E35: Sincere (1)
A37: Skill | E37: Observation | AB37: =_xlfn.XLOOKUP(E39,BroadSkills,BroadSkillAspects,"",0,1) -> Mind | AH37: 6 | AL37: =IF(_ACTR_4>0,_ACTR_4,"") -> 2 | AP37: 9
A39: Umb | E39: Infiltration
AH40: blk | AN40: dg | AP40: =P41 -> 0
A41: Edges, etc. | AF41: =_AE_CCost_4 -> 0 | AU41: Wounds | BD41: Strain | BM41: Strain | BV41: Wounds | CF41: Other Skills | DB41: B/M | DH41: SR | DL41: TR | DP41: TN
AM43: init | AP43: =IFERROR(ATR_4-MAX(A_Bulk_4,AR_Bulk),"") -> 2 | CF43: Skill | CJ43: Beuracracy | DB43: =_xlfn.XLOOKUP(CJ45,BroadSkills,BroadSkillAspects,"",0,1) -> Mind | DH43: 3 | DL43: =IF(_OCTR_1>0,_OCTR_1,"") -> 1 | DP43: 9
AU44: Devotion | BG44: base | BM44: Favor
CF45: Umb | CJ45: Knowledge
DN46: blk
A47: Skill | E47: Security | AB47: =_xlfn.XLOOKUP(E49,BroadSkills,BroadSkillAspects,"",0,1) -> Mind | AH47: 3 | AL47: =IF(_ACTR_5>0,_ACTR_5,"") -> 1 | AP47: 9 | CF47: Edges, etc. | CX47: 0 | DF47: 0
A49: Umb | E49: Infiltration
AH50: blk | AN50: dg | AP50: =P51 -> 0
A51: Edges, etc. | AF51: =_AE_CCost_5 -> 0
AU52: Spirit | BD52: Will
AM53: init | AP53: =IFERROR(ATR_5-MAX(A_Bulk_5,AR_Bulk),"") -> 1 | CF53: Skill | CJ53: Jungle | DB53: =_xlfn.XLOOKUP(CJ55,BroadSkills,BroadSkillAspects,"",0,1) -> Mind | DH53: 4 | DL53: =IF(_OCTR_2>0,_OCTR_2,"") -> 1 | DP53: 8
AU55: Motivations & Goals | CF55: Umb | CJ55: Survival
DN56: blk
A57: Skill | E57: Energy Pistol | AB57: =_xlfn.XLOOKUP(E59,BroadSkills,BroadSkillAspects,"",0,1) -> Body | AH57: 4 | AL57: =IF(_ACTR_6>0,_ACTR_6,"") -> 1 | AP57: 9 | CF57: Edges, etc. | CX57: 0 | DF57: 0
...

Sheet Skill Calcs
A1: Ct | B1: Rank | C1: Total | D1: Title | F1: Umbrella Skills | G1: Aspect | J1: Skill | K1: Rank | L1: Tier | M1: Target | N1: Cost | O1: SR Idx | P1: TN Idx | Q1: TechCost | R1: Override
A2: 0 | B2: 0 | C2: 0 | F2: Athletics | G2: Body | J2: A1 | K2: =A_SR_1 -> 6 | L2: {=INDEX('Tier Calcs'!$A$33:$N$46,O2,P2)} -> 2 | M2: =IF(A_TN_1>0,A_TN_1,9) -> 8 | N2: =_xlfn.IFNA(LOOKUP(K2,$A$3:$C$14,$C$3:$C$14),"") -> 21 | O2: =MATCH(K2,'Tier Calcs'!$A$33:$A$46,0) -> 8 | P2: =MATCH(M2,'Tier Calcs'!$A$33:$N$33,0) -> 10
A3: 1 | B3: 1 | C3: =B3+C2 -> 1 | D3: Novice | F3: Cognition | G3: Mind | J3: A2 | K3: =A_SR_2 -> 3 | L3: {=INDEX('Tier Calcs'!$A$33:$N$46,O3,P3)} -> 1 | M3: =IF(A_TN_2>0,A_TN_2,9) -> 8 | N3: =_xlfn.IFNA(LOOKUP(K3,$A$3:$C$14,$C$3:$C$14),"") -> 6 | O3: =MATCH(K3,'Tier Calcs'!$A$33:$A$46,0) -> 5 | P3: =MATCH(M3,'Tier Calcs'!$A$33:$N$33,0) -> 10
A4: 2 | B4: 2 | C4: =B4+C3 -> 3 | D4: Amateur | F4: Combat: Brutal | G4: Body | J4: A3 | K4: =A_SR_3 -> 4 | L4: {=INDEX('Tier Calcs'!$A$33:$N$46,O4,P4)} -> 1 | M4: =IF(A_TN_3>0,A_TN_3,9) -> 8 | N4: =_xlfn.IFNA(LOOKUP(K4,$A$3:$C$14,$C$3:$C$14),"") -> 10 | O4: =MATCH(K4,'Tier Calcs'!$A$33:$A$46,0) -> 6 | P4: =MATCH(M4,'Tier Calcs'!$A$33:$N$33,0) -> 10
A5: 3 | B5: 3 | C5: =B5+C4 -> 6 | D5: Competent | F5: Combat: Close | G5: Body | J5: A4 | K5: =A_SR_4 -> 6 | L5: {=INDEX('Tier Calcs'!$A$33:$N$46,O5,P5)} -> 2 | M5: =IF(A_TN_4>0,A_TN_4,9) -> 9 | N5: =_xlfn.IFNA(LOOKUP(K5,$A$3:$C$14,$C$3:$C$14),"") -> 21 | O5: =MATCH(K5,'Tier Calcs'!$A$33:$A$46,0) -> 8 | P5: =MATCH(M5,'Tier Calcs'!$A$33:$N$33,0) -> 11
A6: 4 | B6: 4 | C6: =B6+C5 -> 10 | D6: Practiced | F6: Combat: Finesse | G6: Body | J6: A5 | K6: =A_SR_5 -> 3 | L6: {=INDEX('Tier Calcs'!$A$33:$N$46,O6,P6)} -> 1 | M6: =IF(A_TN_5>0,A_TN_5,9) -> 9 | N6: =_xlfn.IFNA(LOOKUP(K6,$A$3:$C$14,$C$3:$C$14),"") -> 6 | O6: =MATCH(K6,'Tier Calcs'!$A$33:$A$46,0) -> 5 | P6: =MATCH(M6,'Tier Calcs'!$A$33:$N$33,0) -> 11
A7: 5 | B7: 5 | C7: =B7+C6 -> 15 | D7: Proficient | F7: Combat: Firearms | G7: Body | J7: A6 | K7: =A_SR_6 -> 4 | L7: {=INDEX('Tier Calcs'!$A$33:$N$46,O7,P7)} -> 1 | M7: =IF(A_TN_6>0,A_TN_6,9) -> 9 | N7: =_xlfn.IFNA(LOOKUP(K7,$A$3:$C$14,$C$3:$C$14),"") -> 10 | O7: =MATCH(K7,'Tier Calcs'!$A$33:$A$46,0) -> 6 | P7: =MATCH(M7,'Tier Calcs'!$A$33:$N$33,0) -> 11
A8: 6 | B8: 6 | C8: =B8+C7 -> 21 | D8: Adept | F8: Combat: Missile | G8: Body | J8: A7 | K8: =A_SR_7 -> 4 | L8: {=INDEX('Tier Calcs'!$A$33:$N$46,O8,P8)} -> 1 | M8: =IF(A_TN_7>0,A_TN_7,9) -> 9 | N8: =_xlfn.IFNA(LOOKUP(K8,$A$3:$C$14,$C$3:$C$14),"") -> 10 | O8: =MATCH(K8,'Tier Calcs'!$A$33:$A$46,0) -> 6 | P8: =MATCH(M8,'Tier Calcs'!$A$33:$N$33,0) -> 11
A9: 7 | B9: 7 | C9: =B9+C8 -> 28 | D9: Accomplished | F9: Combat: Thrown | G9: Body | J9: A8 | K9: =A_SR_8 -> 3 | L9: {=INDEX('Tier Calcs'!$A$33:$N$46,O9,P9)} -> 1 | M9: =IF(A_TN_8>0,A_TN_8,9) -> 9 | N9: =_xlfn.IFNA(LOOKUP(K9,$A$3:$C$14,$C$3:$C$14),"") -> 6 | O9: =MATCH(K9,'Tier Calcs'!$A$33:$A$46,0) -> 5 | P9: =MATCH(M9,'Tier Calcs'!$A$33:$N$33,0) -> 11
A10: 8 | B10: 8 | C10: =B10+C9 -> 36 | D10: Veteran | F10: Coordination | G10: Body | J10: A9 | K10: =A_SR_9 -> 2 | L10: {=INDEX('Tier Calcs'!$A$33:$N$46,O10,P10)} -> 0 | M10: =IF(A_TN_9>0,A_TN_9,9) -> 9 | N10: =_xlfn.IFNA(LOOKUP(K10,$A$3:$C$14,$C$3:$C$14),"") -> 3 | O10: =MATCH(K10,'Tier Calcs'!$A$33:$A$46,0) -> 4 | P10: =MATCH(M10,'Tier Calcs'!$A$33:$N$33,0) -> 11
A11: 9 | B11: 9 | C11: =B11+C10 -> 45 | D11: Expert | F11: Craft | G11: Mind | J11: O1 | K11: =O_SR_1 -> 3 | L11: {=INDEX('Tier Calcs'!$A$33:$N$46,O11,P11)} -> 1 | M11: =IF(O_TN_1,O_TN_1,9) -> 9 | N11: =_xlfn.IFNA(LOOKUP(K11,$A$3:$C$14,$C$3:$C$14),"") -> 6 | O11: =MATCH(K11,'Tier Calcs'!$A$33:$A$46,0) -> 5 | P11: =MATCH(M11,'Tier Calcs'!$A$33:$N$33,0) -> 11
A12: 10 | B12: 10 | C12: =B12+C11 -> 55 | D12: Master | F12: Handling | G12: Mind | J12: O2 | K12: =O_SR_2 -> 4 | L12: {=INDEX('Tier Calcs'!$A$33:$N$46,O12,P12)} -> 1 | M12: =IF(O_TN_2,O_TN_2,9) -> 8 | N12: =_xlfn.IFNA(LOOKUP(K12,$A$3:$C$14,$C$3:$C$14),"") -> 10 | O12: =MATCH(K12,'Tier Calcs'!$A$33:$A$46,0) -> 6 | P12: =MATCH(M12,'Tier Calcs'!$A$33:$N$33,0) -> 10
A13: 11 | B13: 11 | C13: =B13+C12 -> 66 | D13: Renowned | F13: Infiltration | G13: Mind | J13: O3 | K13: =O_SR_3 -> 3 | L13: {=INDEX('Tier Calcs'!$A$33:$N$46,O13,P13)} -> 1 | M13: =IF(O_TN_3,O_TN_3,9) -> 8 | N13: =_xlfn.IFNA(LOOKUP(K13,$A$3:$C$14,$C$3:$C$14),"") -> 6 | O13: =MATCH(K13,'Tier Calcs'!$A$33:$A$46,0) -> 5 | P13: =MATCH(M13,'Tier Calcs'!$A$33:$N$33,0) -> 10
A14: 12 | B14: 12 | C14: =B14+C13 -> 78 | D14: Legendary | F14: Influence | G14: Mind | J14: O4 | K14: =O_SR_4 -> 3 | L14: {=INDEX('Tier Calcs'!$A$33:$N$46,O14,P14)} -> 1 | M14: =IF(O_TN_4,O_TN_4,9) -> 9 | N14: =_xlfn.IFNA(LOOKUP(K14,$A$3:$C$14,$C$3:$C$14),"") -> 6 | O14: =MATCH(K14,'Tier Calcs'!$A$33:$A$46,0) -> 5 | P14: =MATCH(M14,'Tier Calcs'!$A$33:$N$33,0) -> 11
F15: Knowledge | G15: Mind | J15: Lang | K15: =Lang_SR -> 6 | L15: {=INDEX('Tier Calcs'!$A$33:$N$46,O15,P15)} -> 2 | M15: =IF(Lang_TN,Lang_TN,9) -> 9 | N15: =_xlfn.IFNA(LOOKUP(K15,$A$3:$C$14,$C$3:$C$14),"") -> 21 | O15: =MATCH(K15,'Tier Calcs'!$A$33:$A$46,0) -> 8 | P15: =MATCH(M15,'Tier Calcs'!$A$33:$N$33,0) -> 11 | R15: -21
F16: Language | G16: Mind | N16: =SUM(N2:N15) -> 142 | Q16: =SUM(Q2:Q15) -> 0 | R16: =SUM(R2:R15) -> -21
F17: Performance | G17: Mind | N17: =SUM(N16,Q16:R16) -> 121
F18: Piloting | G18: Mind
F19: Survival | G19: Mind

Sheet Edge Calcs
A1: Edges | B1: Potency | C1: Area | D1: Range | E1: Duration | F1: Boost | G1: Bolster | H1: Enhance | I1: Sleek | J1: Advantages | K1: Disadvantages | L1: Cost | M1: Bulk
A2: A1 | B2: =A_Potency_1/3 -> 0 | C2: =A_Area_1/3 -> 0 | D2: =A_Range_1/3 -> 0 | E2: =A_Dura_1/3 -> 0 | F2: =_xlfn.XLOOKUP(A_Boost_1,Parameters!$C$33:$C$45,Parameters!$A$33:$A$45,0,0,2)/3 -> 0 | G2: =_xlfn.XLOOKUP(A_Bolster_1,Parameters!$C$33:$C$45,Parameters!$A$33:$A$45,0,0,2)/3 -> 0 | H2: =_xlfn.XLOOKUP(A_Enhance_1,Parameters!$C$33:$C$45,Parameters!$A$33:$A$45,0,0,2) -> 0 | I2: =A_Sleek_1/3 -> 0 | L2: =IF(ROUNDDOWN(SUM(B2:I2),0)>A_SR_1,ROUNDDOWN(SUM(B2:I2),0)-A_SR_1,0) -> 0 | M2: =IF(ROUNDDOWN(SUM(B2:H2),0)-A_Sleek_1<0,0,ROUNDDOWN(SUM(B2:H2),0)-A_Sleek_1) -> 0
A3: A2 | B3: =A_Potency_2/3 -> 0 | C3: =A_Area_2/3 -> 0 | D3: =A_Range_2/3 -> 0 | E3: =A_Dura_2/3 -> 0 | F3: =_xlfn.XLOOKUP(A_Boost_2,Parameters!$C$33:$C$45,Parameters!$A$33:$A$45,0,0,2)/3 -> 0 | G3: =_xlfn.XLOOKUP(A_Bolster_2,Parameters!$C$33:$C$45,Parameters!$A$33:$A$45,0,0,2)/3 -> 0 | H3: =_xlfn.XLOOKUP(A_Enhance_2,Parameters!$C$33:$C$45,Parameters!$A$33:$A$45,0,0,2) -> 0 | I3: =A_Sleek_2/3 -> 0 | L3: =IF(ROUNDDOWN(SUM(B3:I3),0)>A_SR_1,ROUNDDOWN(SUM(B3:I3),0)-A_SR_2,0) -> 0 | M3: =IF(ROUNDDOWN(SUM(B3:H3),0)-A_Sleek_2<0,0,ROUNDDOWN(SUM(B3:H3),0)-A_Sleek_2) -> 0
A4: A3 | B4: =A_Potency_3/3 -> 0 | C4: =A_Area_3/3 -> 0 | D4: =A_Range_3/3 -> 0 | E4: =A_Dura_3/3 -> 0 | F4: =_xlfn.XLOOKUP(A_Boost_3,Parameters!$C$33:$C$45,Parameters!$A$33:$A$45,0,0,2)/3 -> 0 | G4: =_xlfn.XLOOKUP(A_Bolster_3,Parameters!$C$33:$C$45,Parameters!$A$33:$A$45,0,0,2)/3 -> 0 | H4: =_xlfn.XLOOKUP(A_Enhance_3,Parameters!$C$33:$C$45,Parameters!$A$33:$A$45,0,0,2) -> 0 | I4: =A_Sleek_3/3 -> 0 | L4: =IF(ROUNDDOWN(SUM(B4:I4),0)>A_SR_1,ROUNDDOWN(SUM(B4:I4),0)-A_SR_3,0) -> 0 | M4: =IF(ROUNDDOWN(SUM(B4:H4),0)-A_Sleek_3<0,0,ROUNDDOWN(SUM(B4:H4),0)-A_Sleek_3) -> 0
A5: A4 | B5: =A_Potency_4/3 -> 0 | C5: =A_Area_4/3 -> 0 | D5: =A_Range_4/3 -> 0 | E5: =A_Dura_4/3 -> 0 | F5: =_xlfn.XLOOKUP(A_Boost_4,Parameters!$C$33:$C$45,Parameters!$A$33:$A$45,0,0,2)/3 -> 0 | G5: =_xlfn.XLOOKUP(A_Bolster_4,Parameters!$C$33:$C$45,Parameters!$A$33:$A$45,0,0,2)/3 -> 0 | H5: =_xlfn.XLOOKUP(A_Enhance_4,Parameters!$C$33:$C$45,Parameters!$A$33:$A$45,0,0,2) -> 0 | I5: =A_Sleek_4/3 -> 0 | L5: =IF(ROUNDDOWN(SUM(B5:I5),0)>A_SR_1,ROUNDDOWN(SUM(B5:I5),0)-A_SR_4,0) -> 0 | M5: =IF(ROUNDDOWN(SUM(B5:H5),0)-A_Sleek_4<0,0,ROUNDDOWN(SUM(B5:H5),0)-A_Sleek_4) -> 0
A6: A5 | B6: =A_Potency_5/3 -> 0 | C6: =A_Area_5/3 -> 0 | D6: =A_Range_5/3 -> 0 | E6: =A_Dura_5/3 -> 0 | F6: =_xlfn.XLOOKUP(A_Boost_5,Parameters!$C$33:$C$45,Parameters!$A$33:$A$45,0,0,2)/3 -> 0 | G6: =_xlfn.XLOOKUP(A_Bolster_5,Parameters!$C$33:$C$45,Parameters!$A$33:$A$45,0,0,2)/3 -> 0 | H6: =_xlfn.XLOOKUP(A_Enhance_5,Parameters!$C$33:$C$45,Parameters!$A$33:$A$45,0,0,2) -> 0 | I6: =A_Sleek_5/3 -> 0 | L6: =IF(ROUNDDOWN(SUM(B6:I6),0)>A_SR_1,ROUNDDOWN(SUM(B6:I6),0)-A_SR_5,0) -> 0 | M6: =IF(ROUNDDOWN(SUM(B6:H6),0)-A_Sleek_5<0,0,ROUNDDOWN(SUM(B6:H6),0)-A_Sleek_5) -> 0
A7: A6 | B7: =A_Potency_6/3 -> 0 | C7: =A_Area_6/3 -> 0 | D7: =A_Range_6/3 -> 0 | E7: =A_Dura_6/3 -> 0 | F7: =_xlfn.XLOOKUP(A_Boost_6,Parameters!$C$33:$C$45,Parameters!$A$33:$A$45,0,0,2)/3 -> 0 | G7: =_xlfn.XLOOKUP(A_Bolster_6,Parameters!$C$33:$C$45,Parameters!$A$33:$A$45,0,0,2)/3 -> 0 | H7: =_xlfn.XLOOKUP(A_Enhance_6,Parameters!$C$33:$C$45,Parameters!$A$33:$A$45,0,0,2) -> 0 | I7: =A_Sleek_6/3 -> 0 | L7: =IF(ROUNDDOWN(SUM(B7:I7),0)>A_SR_1,ROUNDDOWN(SUM(B7:I7),0)-A_SR_6,0) -> 0 | M7: =IF(ROUNDDOWN(SUM(B7:H7),0)-A_Sleek_6<0,0,ROUNDDOWN(SUM(B7:H7),0)-A_Sleek_6) -> 0
A8: A7 | B8: =A_Potency_7/3 -> 0 | C8: =A_Area_7/3 -> 0 | D8: =A_Range_7/3 -> 0 | E8: =A_Dura_7/3 -> 0 | F8: =_xlfn.XLOOKUP(A_Boost_7,Parameters!$C$33:$C$45,Parameters!$A$33:$A$45,0,0,2)/3 -> 0 | G8: =_xlfn.XLOOKUP(A_Bolster_7,Parameters!$C$33:$C$45,Parameters!$A$33:$A$45,0,0,2)/3 -> 0 | H8: =_xlfn.XLOOKUP(A_Enhance_7,Parameters!$C$33:$C$45,Parameters!$A$33:$A$45,0,0,2) -> 0 | I8: =A_Sleek_7/3 -> 0 | L8: =IF(ROUNDDOWN(SUM(B8:I8),0)>A_SR_1,ROUNDDOWN(SUM(B8:I8),0)-A_SR_7,0) -> 0 | M8: =IF(ROUNDDOWN(SUM(B8:H8),0)-A_Sleek_7<0,0,ROUNDDOWN(SUM(B8:H8),0)-A_Sleek_7) -> 0
A9: A8 | B9: =A_Potency_8/3 -> 0 | C9: =A_Area_8/3 -> 0 | D9: =A_Range_8/3 -> 0 | E9: =A_Dura_8/3 -> 0 | F9: =_xlfn.XLOOKUP(A_Boost_8,Parameters!$C$33:$C$45,Parameters!$A$33:$A$45,0,0,2)/3 -> 0 | G9: =_xlfn.XLOOKUP(A_Bolster_8,Parameters!$C$33:$C$45,Parameters!$A$33:$A$45,0,0,2)/3 -> 0 | H9: =_xlfn.XLOOKUP(A_Enhance_8,Parameters!$C$33:$C$45,Parameters!$A$33:$A$45,0,0,2) -> 0 | I9: =A_Sleek_8/3 -> 0 | L9: =IF(ROUNDDOWN(SUM(B9:I9),0)>A_SR_1,ROUNDDOWN(SUM(B9:I9),0)-A_SR_8,0) -> 0 | M9: =IF(ROUNDDOWN(SUM(B9:H9),0)-A_Sleek_8<0,0,ROUNDDOWN(SUM(B9:H9),0)-A_Sleek_8) -> 0
A10: A9 | B10: =A_Potency_9/3 -> 0 | C10: =A_Area_9/3 -> 0 | D10: =A_Range_9/3 -> 0 | E10: =A_Dura_9/3 -> 0 | F10: =_xlfn.XLOOKUP(A_Boost_9,Parameters!$C$33:$C$45,Parameters!$A$33:$A$45,0,0,2)/3 -> 0 | G10: =_xlfn.XLOOKUP(A_Bolster_9,Parameters!$C$33:$C$45,Parameters!$A$33:$A$45,0,0,2)/3 -> 0 | H10: =_xlfn.XLOOKUP(A_Enhance_9,Parameters!$C$33:$C$45,Parameters!$A$33:$A$45,0,0,2) -> 0 | I10: =A_Sleek_9/3 -> 0 | L10: =IF(ROUNDDOWN(SUM(B10:I10),0)>A_SR_1,ROUNDDOWN(SUM(B10:I10),0)-A_SR_9,0) -> 0 | M10: =IF(ROUNDDOWN(SUM(B10:H10),0)-A_Sleek_9<0,0,ROUNDDOWN(SUM(B10:H10),0)-A_Sleek_9) -> 0
A11: O1 | B11: =O_Potency_1/3 -> 0 | C11: =O_Area_1/3 -> 0 | D11: =O_Range_1/3 -> 0 | E11: =O_Dura_1/3 -> 0 | F11: =_xlfn.XLOOKUP(O_Boost_1,Parameters!$C$33:$C$45,Parameters!$A$33:$A$45,0,0,2)/3 -> 0 | G11: =_xlfn.XLOOKUP(O_Bolster_1,Parameters!$C$33:$C$45,Parameters!$A$33:$A$45,0,0,2)/3 -> 0 | H11: =_xlfn.XLOOKUP(O_Enhance_1,Parameters!$C$33:$C$45,Parameters!$A$33:$A$45,0,0,2) -> 0 | I11: =O_Sleek_1/3 -> 0 | L11: =IF(ROUNDDOWN(SUM(B11:I11),0)>O_SR_1,ROUNDDOWN(SUM(B11:I11),0)-O_SR_1,0) -> 0 | M11: =IF(ROUNDDOWN(SUM(B11:H11),0)-O_Sleek_1<0,0,ROUNDDOWN(SUM(B11:H11),0)-O_Sleek_1) -> 0
A12: O2 | B12: =O_Potency_2/3 -> 0 | C12: =O_Area_2/3 -> 0 | D12: =O_Range_2/3 -> 0 | E12: =O_Dura_2/3 -> 0 | F12: =_xlfn.XLOOKUP(O_Boost_2,Parameters!$C$33:$C$45,Parameters!$A$33:$A$45,0,0,2)/3 -> 0 | G12: =_xlfn.XLOOKUP(O_Bolster_2,Parameters!$C$33:$C$45,Parameters!$A$33:$A$45,0,0,2)/3 -> 0 | H12: =_xlfn.XLOOKUP(O_Enhance_2,Parameters!$C$33:$C$45,Parameters!$A$33:$A$45,0,0,2) -> 0 | I12: =O_Sleek_2/3 -> 0 | L12: =IF(ROUNDDOWN(SUM(B12:I12),0)>O_SR_2,ROUNDDOWN(SUM(B12:I12),0)-O_SR_2,0) -> 0 | M12: =IF(ROUNDDOWN(SUM(B12:H12),0)-O_Sleek_2<0,0,ROUNDDOWN(SUM(B12:H12),0)-O_Sleek_2) -> 0
A13: O3 | B13: =O_Potency_3/3 -> 0 | C13: =O_Area_3/3 -> 0 | D13: =O_Range_3/3 -> 0 | E13: =O_Dura_3/3 -> 0 | F13: =_xlfn.XLOOKUP(O_Boost_3,Parameters!$C$33:$C$45,Parameters!$A$33:$A$45,0,0,2)/3 -> 0 | G13: =_xlfn.XLOOKUP(O_Bolster_3,Parameters!$C$33:$C$45,Parameters!$A$33:$A$45,0,0,2)/3 -> 0 | H13: =_xlfn.XLOOKUP(O_Enhance_3,Parameters!$C$33:$C$45,Parameters!$A$33:$A$45,0,0,2) -> 0 | I13: =O_Sleek_3/3 -> 0 | L13: =IF(ROUNDDOWN(SUM(B13:I13),0)>O_SR_3,ROUNDDOWN(SUM(B13:I13),0)-O_SR_3,0) -> 0 | M13: =IF(ROUNDDOWN(SUM(B13:H13),0)-O_Sleek_3<0,0,ROUNDDOWN(SUM(B13:H13),0)-O_Sleek_3) -> 0
A14: O4 | B14: =O_Potency_4/3 -> 0 | C14: =O_Area_4/3 -> 0 | D14: =O_Range_4/3 -> 0 | E14: =O_Dura_4/3 -> 0 | F14: =_xlfn.XLOOKUP(O_Boost_4,Parameters!$C$33:$C$45,Parameters!$A$33:$A$45,0,0,2)/3 -> 0 | G14: =_xlfn.XLOOKUP(O_Bolster_4,Parameters!$C$33:$C$45,Parameters!$A$33:$A$45,0,0,2)/3 -> 0 | H14: =_xlfn.XLOOKUP(O_Enhance_4,Parameters!$C$33:$C$45,Parameters!$A$33:$A$45,0,0,2) -> 0 | I14: =O_Sleek_4/3 -> 0 | L14: =IF(ROUNDDOWN(SUM(B14:I14),0)>O_SR_4,ROUNDDOWN(SUM(B14:I14),0)-O_SR_4,0) -> 0 | M14: =IF(ROUNDDOWN(SUM(B14:H14),0)-O_Sleek_4<0,0,ROUNDDOWN(SUM(B14:H14),0)-O_Sleek_4) -> 0
K15: Total Cost | L15: =SUM(L2:L14) -> 0

Sheet Tier Calcs
A2: Facing | B2: TN 1 | C2: TN 2 | D2: TN 3 | E2: TN 4 | F2: TN 5 | G2: TN 6 | H2: TN 7 | I2: TN 8 | J2: TN 9 | K2: TN 10 | L2: TN 11 | M2: TN 12
A3: 1 | B3: 0
A4: 2 | B4: 0 | C4: 1
A5: 3 | B5: 0 | C5: 1 | D5: 1
A6: 4 | B6: 0 | C6: 1 | D6: 1 | E6: 1
A7: 5 | B7: 0 | C7: 1 | D7: 1 | E7: 1 | F7: 1
A8: 6 | B8: 0 | C8: 1 | D8: 1 | E8: 1 | F8: 1 | G8: 1
A9: 7 | B9: 0 | C9: 1 | D9: 1 | E9: 1 | F9: 1 | G9: 1 | H9: 1
A10: 8 | B10: 0 | C10: 1 | D10: 1 | E10: 1 | F10: 1 | G10: 1 | H10: 1 | I10: 1
A11: 9 | B11: 0 | C11: 1 | D11: 1 | E11: 1 | F11: 1 | G11: 1 | H11: 1 | I11: 1 | J11: 1
A12: 10 | B12: 0 | C12: 1 | D12: 1 | E12: 1 | F12: 1 | G12: 1 | H12: 1 | I12: 1 | J12: 1 | K12: 1
A13: 11 | B13: 0 | C13: 1 | D13: 1 | E13: 1 | F13: 1 | G13: 1 | H13: 1 | I13: 1 | J13: 1 | K13: 1 | L13: 1
A14: 12 | B14: 0 | C14: 1 | D14: 1 | E14: 1 | F14: 1 | G14: 1 | H14: 1 | I14: 1 | J14: 1 | K14: 1 | L14: 1 | M14: 1
B15: =(SUM(B3:B14)/12) -> 0 | C15: =(SUM(C3:C14)/12) -> 0.91666667 | D15: =(SUM(D3:D14)/12) -> 0.83333333 | E15: =(SUM(E3:E14)/12) -> 0.75 | F15: =(SUM(F3:F14)/12) -> 0.66666667 | G15: =(SUM(G3:G14)/12) -> 0.58333333 | H15: =(SUM(H3:H14)/12) -> 0.5 | I15: =(SUM(I3:I14)/12) -> 0.41666667 | ... M15: =(SUM(M3:M14)/12) -> 0.083333333
B17: Number of Dice
A18: TN | B18: 1 | C18: 2 | D18: 3 | E18: 4 | F18: 5 | G18: 6 | H18: 7 | I18: 8 | J18: 9 | K18: 10 | L18: 11 | M18: 12
A19: 1 | B19: =$B$15*B$18 -> 0 | C19: =$B$15*C$18 -> 0 | D19: =$B$15*D$18 -> 0 | E19: =$B$15*E$18 -> 0 | F19: =$B$15*F$18 -> 0 | G19: =$B$15*G$18 -> 0 | H19: =$B$15*H$18 -> 0 | I19: =$B$15*I$18 -> 0 | ... M19: =$B$15*M$18 -> 0
A20: 2 | B20: =$C$15*B$18 -> 0.91666667 | C20: =$C$15*C$18 -> 1.8333333 | D20: =$C$15*D$18 -> 2.75 | E20: =$C$15*E$18 -> 3.6666667 | F20: =$C$15*F$18 -> 4.5833333 | G20: =$C$15*G$18 -> 5.5 | H20: =$C$15*H$18 -> 6.4166667 | I20: =$C$15*I$18 -> 7.3333333 | ... M20: =$C$15*M$18 -> 11
A21: 3 | B21: =$D$15*B$18 -> 0.83333333 | C21: =$D$15*C$18 -> 1.6666667 | D21: =$D$15*D$18 -> 2.5 | E21: =$D$15*E$18 -> 3.3333333 | F21: =$D$15*F$18 -> 4.1666667 | G21: =$D$15*G$18 -> 5 | H21: =$D$15*H$18 -> 5.8333333 | I21: =$D$15*I$18 -> 6.6666667 | ... M21: =$D$15*M$18 -> 10
A22: 4 | B22: =$E$15*B$18 -> 0.75 | C22: =$E$15*C$18 -> 1.5 | D22: =$E$15*D$18 -> 2.25 | E22: =$E$15*E$18 -> 3 | F22: =$E$15*F$18 -> 3.75 | G22: =$E$15*G$18 -> 4.5 | H22: =$E$15*H$18 -> 5.25 | I22: =$E$15*I$18 -> 6 | ... M22: =$E$15*M$18 -> 9
A23: 5 | B23: =$F$15*B$18 -> 0.66666667 | C23: =$F$15*C$18 -> 1.3333333 | D23: =$F$15*D$18 -> 2 | E23: =$F$15*E$18 -> 2.6666667 | F23: =$F$15*F$18 -> 3.3333333 | G23: =$F$15*G$18 -> 4 | H23: =$F$15*H$18 -> 4.6666667 | I23: =$F$15*I$18 -> 5.3333333 | ... M23: =$F$15*M$18 -> 8
A24: 6 | B24: =$G$15*B$18 -> 0.58333333 | C24: =$G$15*C$18 -> 1.1666667 | D24: =$G$15*D$18 -> 1.75 | E24: =$G$15*E$18 -> 2.3333333 | F24: =$G$15*F$18 -> 2.9166667 | G24: =$G$15*G$18 -> 3.5 | H24: =$G$15*H$18 -> 4.0833333 | I24: =$G$15*I$18 -> 4.6666667 | ... M24: =$G$15*M$18 -> 7
A25: 7 | B25: =$H$15*B$18 -> 0.5 | C25: =$H$15*C$18 -> 1 | D25: =$H$15*D$18 -> 1.5 | E25: =$H$15*E$18 -> 2 | F25: =$H$15*F$18 -> 2.5 | G25: =$H$15*G$18 -> 3 | H25: =$H$15*H$18 -> 3.5 | I25: =$H$15*I$18 -> 4 | ... M25: =$H$15*M$18 -> 6
A26: 8 | B26: =$I$15*B$18 -> 0.41666667 | C26: =$I$15*C$18 -> 0.83333333 | D26: =$I$15*D$18 -> 1.25 | E26: =$I$15*E$18 -> 1.6666667 | F26: =$I$15*F$18 -> 2.0833333 | G26: =$I$15*G$18 -> 2.5 | H26: =$I$15*H$18 -> 2.9166667 | I26: =$I$15*I$18 -> 3.3333333 | ... M26: =$I$15*M$18 -> 5
A27: 9 | B27: =$J$15*B$18 -> 0.33333333 | C27: =$J$15*C$18 -> 0.66666667 | D27: =$J$15*D$18 -> 1 | E27: =$J$15*E$18 -> 1.3333333 | F27: =$J$15*F$18 -> 1.6666667 | G27: =$J$15*G$18 -> 2 | H27: =$J$15*H$18 -> 2.3333333 | I27: =$J$15*I$18 -> 2.6666667 | ... M27: =$J$15*M$18 -> 4
A28: 10 | B28: =$K$15*B$18 -> 0.25 | C28: =$K$15*C$18 -> 0.5 | D28: =$K$15*D$18 -> 0.75 | E28: =$K$15*E$18 -> 1 | F28: =$K$15*F$18 -> 1.25 | G28: =$K$15*G$18 -> 1.5 | H28: =$K$15*H$18 -> 1.75 | I28: =$K$15*I$18 -> 2 | ... M28: =$K$15*M$18 -> 3
A29: 11 | B29: =$L$15*B$18 -> 0.16666667 | C29: =$L$15*C$18 -> 0.33333333 | D29: =$L$15*D$18 -> 0.5 | E29: =$L$15*E$18 -> 0.66666667 | F29: =$L$15*F$18 -> 0.83333333 | G29: =$L$15*G$18 -> 1 | H29: =$L$15*H$18 -> 1.1666667 | I29: =$L$15*I$18 -> 1.3333333 | ... M29: =$L$15*M$18 -> 2
A30: 12 | B30: =$M$15*B$18 -> 0.083333333 | C30: =$M$15*C$18 -> 0.16666667 | D30: =$M$15*D$18 -> 0.25 | E30: =$M$15*E$18 -> 0.33333333 | F30: =$M$15*F$18 -> 0.41666667 | G30: =$M$15*G$18 -> 0.5 | H30: =$M$15*H$18 -> 0.58333333 | I30: =$M$15*I$18 -> 0.66666667 | ... M30: =$M$15*M$18 -> 1
A32: Tier | B32: Target Number
A33: S Rank | B33: 0 | C33: 1 | D33: 2 | E33: 3 | F33: 4 | G33: 5 | H33: 6 | I33: 7 | J33: 8 | K33: 9 | L33: 10 | M33: 11 | N33: 12
A34: 0 | B34: 0 | C34: 0 | D34: 0 | E34: 0 | F34: 0 | G34: 0 | H34: 0 | I34: 0 | J34: 0 | K34: 0 | L34: 0 | M34: 0 | N34: 0
A35: 1 | B35: 0 | C35: 0 | D35: 0 | E35: 0 | F35: 0 | G35: 0 | H35: 0 | I35: 0 | J35: 0 | K35: 0 | L35: 0 | M35: 0 | N35: 0
A36: 2 | B36: 0 | C36: 0 | D36: 1 | E36: 1 | F36: 1 | G36: 1 | H36: 1 | I36: 1 | J36: 0 | K36: 0 | L36: 0 | M36: 0 | N36: 0
A37: 3 | B37: 0 | C37: 0 | D37: 2 | E37: 2 | F37: 2 | G37: 2 | H37: 1 | I37: 1 | J37: 1 | K37: 1 | L37: 0 | M37: 0 | N37: 0
A38: 4 | B38: 0 | C38: 0 | D38: 3 | E38: 3 | F38: 3 | G38: 2 | H38: 2 | I38: 2 | J38: 1 | K38: 1 | L38: 1 | M38: 0 | N38: 0
A39: 5 | B39: 0 | C39: 0 | D39: 4 | E39: 4 | F39: 3 | G39: 3 | H39: 2 | I39: 2 | J39: 2 | K39: 1 | L39: 1 | M39: 0 | N39: 0
A40: 6 | B40: 0 | C40: 0 | D40: 5 | E40: 5 | F40: 4 | G40: 4 | H40: 3 | I40: 3 | J40: 2 | K40: 2 | L40: 1 | M40: 1 | N40: 0
A41: 7 | B41: 0 | C41: 0 | D41: 6 | E41: 5 | F41: 5 | G41: 4 | H41: 3 | I41: 3 | J41: 2 | K41: 2 | L41: 1 | M41: 1 | N41: 0
A42: 8 | B42: 0 | C42: 0 | D42: 7 | E42: 6 | F42: 6 | G42: 5 | H42: 4 | I42: 4 | J42: 3 | K42: 2 | L42: 2 | M42: 1 | N42: 0
A43: 9 | B43: 0 | C43: 0 | D43: 8 | E43: 7 | F43: 6 | G43: 6 | H43: 4 | I43: 4 | J43: 3 | K43: 3 | L43: 2 | M43: 1 | N43: 0
...

Sheet Parameters
A1: Cost | B1: Range & Area (Assign Cost Twice)
A2: 0 | B2: Target | C2: self or target
A3: 1 | B3: Engaged | C3: within reach
A4: 2 | B4: Close | C4: Those you could speak with without shouting in a restaurant
A5: 3 | B5: Short | C5: Those you could play catch with or speak with if you raised your voice
A6: 4 | B6: Near | C6: With Speaker and Microphone they could hear you
A7: 5 | B7: Apart | C7: You could see them unaided if you had 20/20 vision.
A8: =A7*2 -> 10 | B8: Distant | C8: You could walk there in less than an hour
A9: =A8*2 -> 20 | B9: City | C9: You could walk there in a day
A10: =A9*2 -> 40 | B10: Vast | C10: It would take you several days to walk there.
A11: =A10*2 -> 80 | B11: Continent | C11: Landmass away, an epic walk
A12: =A11*2 -> 160 | B12: World | C12: The entire world contained within a Magnetic Field
A13: =A12*2 -> 320 | B13: System | C13: The entire Solar System contained by the Heliosphere of the Sun(s)
A14: =A13*2 -> 640 | B14: Beyond | C14: Pretty much any distance, recommend that it isn't the entire galaxy.
A16: Cost | B16: Durations
A17: 0 | B17: Instant | C17: a heartbeat
A18: 1 | B18: 3 | C18: 3 rounds
A19: 2 | B19: 6 | C19: 6 rounds
A20: 3 | B20: Turn | C20: a spirited exchange between two arguing
A21: 4 | B21: Scene | C21: the entire argument
A22: 6 | B22: Day | C22: the turning of a planet
A23: 12 | B23: Week | C23: a grouping of days, determined by a calendar
A24: 24 | B24: Month | C24: the complete cycle of a astral body
A25: 48 | B25: Season | C25: Solstice to Equinox or vice versa
A26: 96 | B26: Year | C26: the rotation of the planet around a sun
A27: 192 | B27: Decade | C27: 10 rotations
A28: 384 | B28: Lifetime | C28: the lifetime of the target
A29: 768 | B29: Permanent | C29: incalculable duration
A31: Potency
A32: Cost | B32: TN | C32: DL/Reroll | D32: Base
A33: 0 | B33: - | C33: - | D33: -
A34: 1 | B34: - | C34: - | D34: 1
A35: 2 | B35: - | C35: 1 | D35: 2
A36: 3 | B36: 1 | C36: - | D36: 3
A37: 4 | B37: - | C37: 2 | D37: 4
A38: 5 | B38: - | C38: - | D38: 5
A39: 6 | B39: 2 | C39: 3 | D39: 6
A40: 7 | B40: - | C40: - | D40: 7
A41: 8 | B41: - | C41: 4 | D41: 8
A42: 9 | B42: 3 | C42: - | D42: 9
...

Sheet Morals
A1: Moral Code
A2: Conducts | V2: In Tribe | AA2: Out of Tribe | AF2: Cost
A3: Killing | V3: 3 | AA3: 2 | AF3: 0
A5: Lying | V5: 1 | AA5: 0 | AF5: 0
A7: Breaking Word | V7: 4 | AA7: 3 | AF7: 0
A9: Stealing | V9: 2 | AA9: 1 | AF9: 0
A11: Denying Aid | V11: 2 | AA11: 0 | AF11: 0
