Workbook
Name _CTier_1: 'Skill Calcs'!$Q$2
Name _CTR_1: 'Skill Calcs'!$Q$2
Name _CTR_2: 'Skill Calcs'!$Q$3
Name _CTR_3: 'Skill Calcs'!$Q$4
Name _CTR_4: 'Skill Calcs'!$Q$5
Name _CTR_5: 'Skill Calcs'!$Q$6
Name _CTR_6: 'Skill Calcs'!$Q$7
Name _CTR_7: 'Skill Calcs'!$Q$8
Name _CTR_8: 'Skill Calcs'!$Q$9
Name _CTR_9: 'Skill Calcs'!$Q$10
Name _S1_Cost: 'Skill Calcs'!$S$2
Name _Sum_Skill_Costs: 'Skill Calcs'!$S$11
Name BodyBaseSkills: 'Skill Calcs'!$F$8:$F$15
Name MindBaseSkills: 'Skill Calcs'!$F$2:$F$7
Name S_TN_1: Doc!$AP$7
Name S_TN_2: Doc!$AP$17
Name S_TN_3: Doc!$AP$27
Name S_TN_4: Doc!$AP$37
Name S_TN_5: Doc!$AP$47
Name S_TN_6: Doc!$AP$57
Name S_TN_7: Doc!$AP$67
Name S_TN_8: Doc!$AP$77
Name S_TN_9: Doc!$AP$87
Name SR_1: Doc!$AH$7
Name SR_2: Doc!$AH$17
Name SR_3: Doc!$AH$27
Name SR_4: Doc!$AH$37
Name SR_5: Doc!$AH$47
Name SR_6: Doc!$AH$57
Name SR_7: Doc!$AH$67
Name SR_8: Doc!$AH$77
Name SR_9: Doc!$AH$87

Sheet Generate

Sheet Doc
A1: Name: | G1: Kudzu Ringtail (Thor) | BJ1: Species: | BR1: Chinashti | DI1: Untold RPG
A5: Skills: | AB5: B/M | AH5: SR | AL5: TR | AP5: TN | AU5: Body DR | BD5: Wounds & Exertion | BW5: Mind DR | CF5: Weaknesses | DO5: Cost
A7: Skill | E7: Engineer, Civil | AB7: =_xlfn.XLOOKUP(E9,'Skill Calcs'!$F$2:$F$15,'Skill Calcs'!$G$2:$G$15,"",0,1) -> Mind | AH7: 6 | AL7: =IF(_CTR_1>0,_CTR_1,"") -> 2 | AU7: 5 | BW7: 3 | CF7: Distinguishing Trait (Tail/Fur) | DO7: 3
A9: Umb | E9: Knowledge | CF9: Inept (Bodybuilding, Brutal) | DO9: 14
AH10: blk | AN10: dg
A11: Edges, etc. | AU11: Endurance | BG11: base | BI11: =3*(AU7+1) -> 18 | BM11: Tenacity | BY11: base | CA11: =3*(BW7+1) -> 12 | CF11: Obsession (2 DL Curiosity) | DO11: 6
AM13: init | AP13: =AL7-AJ10 -> 2 | CF13: Physical Impairment | DO13: 25
A17: Skill | E17: Mag Vehicles | AB17: =_xlfn.XLOOKUP(E19,'Skill Calcs'!$F$2:$F$15,'Skill Calcs'!$G$2:$G$15,"",0,1) -> Mind | AH17: 6 | AL17: =IF(_CTR_2>0,_CTR_2,"") -> 3 | AP17: 8
A19: Umb | E19: Piloting | AU19: Wounds | BD19: Strain | BM19: Strain | BV19: Wounds
AH20: blk | AN20: dg | CF20: Strengths | DO20: Cost
A21: Edges, etc. | E21: Stunt Pilot (2 rerolls : 12 cost) | AU21: ↘ | BV21: ↙
BD22: Resilience | BP22: base | BR22: =2*(ROUNDUP(MAX(AU7,BW7),0)+1) -> 12 | CF22: Prehensile Tail | DO22: 15
AM23: init | AP23: =AL17-AJ20 -> 3
CF24: Agile (1 TN Coordination & Finesse) | DO24: 32
E25: Agile
CF26: Lithe (+1 BDR) | DO26: 14
A27: Skill | E27: Tailoring/Weaving | AB27: =_xlfn.XLOOKUP(E29,'Skill Calcs'!$F$2:$F$15,'Skill Calcs'!$G$2:$G$15,"",0,1) -> Mind | AH27: 6 | AL27: =IF(_CTR_3>0,_CTR_3,"") -> 3 | AP27: 8 | AU27: ↙ | BV27: ↘
A29: Umb | E29: Craft
AH30: blk | AJ30: 1 | AN30: dg | AP30: - | BD30: Wounds | BM30: Strain
A31: Edges, etc. | E31: Tools (P:6,A,R,D:6-B:2,B,E) 5
E33: Agile | AM33: init | AP33: =AL27-AJ30 -> 2 | AU33: Vitality | BG33: base | BI33: =AU7+3 -> 8 | BM33: Sanity | BY33: base | CA33: =BW7+3 -> 6
A37: Skill | E37: Dueling Weapons | AB37: =_xlfn.XLOOKUP(E39,'Skill Calcs'!$F$2:$F$15,'Skill Calcs'!$G$2:$G$15,"",0,1) -> Body | AH37: 6 | AL37: =IF(_CTR_4>0,_CTR_4,"") -> 4 | AP37: 7
A39: Umb | E39: Combat: Melee
AH40: blk | AJ40: 1 | AN40: dg | AP40: 2
A41: Edges, etc. | E41: Foil (P:2,A,R:1,D:3-B,B,E:1, Sl:3) 6 | AU41: Wounds | BD41: Strain | BM41: Strain | BV41: Wounds | CF41: Gear | CX41: BT | CZ41: P | DB41: R | DD41: BL | DF41: A | DH41: D | DJ41: EN | DL41: Cost | DP41: Bulk
E43: En Guard (1 reroll: 6 cost) | AM43: init | AP43: =AL37-AJ40 -> 3
AU44: Devotion | BG44: base | BM44: Favor
E45: Agile | CF45: Advances
A47: Skill | E47: Jungle | AB47: =_xlfn.XLOOKUP(E49,'Skill Calcs'!$F$2:$F$15,'Skill Calcs'!$G$2:$G$15,"",0,1) -> Mind | AH47: 3 | AL47: =IF(_CTR_5>0,_CTR_5,"") -> 1
A49: Umb | E49: Survival | CF49: Advances
AH50: blk | AN50: dg
A51: Edges, etc.
AU52: Spirit | BD52: Will
AM53: init | AP53: =AL47-AJ50 -> 1 | CF53: Advances
AU55: Motivations & Goals
A57: Skill | E57: Observation | AB57: =_xlfn.XLOOKUP(E59,'Skill Calcs'!$F$2:$F$15,'Skill Calcs'!$G$2:$G$15,"",0,1) -> Mind | AH57: 4 | AL57: =IF(_CTR_6>0,_CTR_6,"") -> 2 | AU57: Perfect Wedding | CF57: Advances
A59: Umb | E59: Infiltration
AH60: blk | AN60: dg
A61: Edges, etc. | E61: Goggles (P,A:4,R:5,D-B:2,B,E,Sl:3) 4 | CF61: Advances
AM63: init | AP63: =AL57-AJ60 -> 2 | AU63: Description & Traits
...

Sheet Skill Calcs
A1: Ct | B1: S | C1: T | D1: Title | F1: Umbrella Skills | G1: Aspect | O1: Skill | P1: Rank | Q1: Tier | R1: Target | S1: Cost | T1: SR Idx | U1: TN Idx | V1: Technique Costs | W1: Override Cost
A2: 0 | B2: 0 | C2: 0 | F2: Athletics | G2: Body | O2: 1 | P2: =SR_1 -> 6 | Q2: {=INDEX('Tier Calcs'!$A$33:$N$46,T2,U2)} -> 2 | R2: =IF(S_TN_1>0,S_TN_1,9) -> 9 | S2: =_xlfn.IFNA(LOOKUP(P2,$A$3:$C$14,$C$3:$C$14),"") -> 21 | T2: =MATCH(P2,'Tier Calcs'!$A$33:$A$46,0) -> 8 | U2: =MATCH(R2,'Tier Calcs'!$A$33:$N$33,0) -> 11
A3: 1 | B3: 1 | C3: =B3 -> 1 | D3: Novice | F3: Cognition | G3: Mind | O3: 2 | P3: =SR_2 -> 6 | Q3: {=INDEX('Tier Calcs'!$A$35:$N$46,T3,U3)} -> 3 | R3: =IF(S_TN_2>0,S_TN_2,9) -> 8 | S3: =_xlfn.IFNA(LOOKUP(P3,$A$3:$C$14,$C$3:$C$14),"") -> 21 | T3: =MATCH(P3,'Tier Calcs'!$A$33:$A$46,0) -> 8 | U3: =MATCH(R3,'Tier Calcs'!$A$33:$N$33,0) -> 10 | V3: 12
A4: 2 | B4: 2 | C4: =B4+C3 -> 3 | D4: Amateur | F4: Combat: Melee | G4: Body | O4: 3 | P4: =SR_3 -> 6 | Q4: {=INDEX('Tier Calcs'!$A$35:$N$46,T4,U4)} -> 3 | R4: =IF(S_TN_3>0,S_TN_3,9) -> 8 | S4: =_xlfn.IFNA(LOOKUP(P4,$A$3:$C$14,$C$3:$C$14),"") -> 21 | T4: =MATCH(P4,'Tier Calcs'!$A$33:$A$46,0) -> 8 | U4: =MATCH(R4,'Tier Calcs'!$A$33:$N$33,0) -> 10
A5: 3 | B5: 3 | C5: =B5+C4 -> 6 | D5: Competent | F5: Combat: Thrown | G5: Body | O5: 4 | P5: =SR_4 -> 6 | Q5: {=INDEX('Tier Calcs'!$A$35:$N$46,T5,U5)} -> 4 | R5: =IF(S_TN_4>0,S_TN_4,9) -> 7 | S5: =_xlfn.IFNA(LOOKUP(P5,$A$3:$C$14,$C$3:$C$14),"") -> 21 | T5: =MATCH(P5,'Tier Calcs'!$A$33:$A$46,0) -> 8 | U5: =MATCH(R5,'Tier Calcs'!$A$33:$N$33,0) -> 9 | V5: 6
A6: 4 | B6: 4 | C6: =B6+C5 -> 10 | D6: Practiced | F6: Coordination | G6: Body | O6: 5 | P6: =SR_5 -> 3 | Q6: {=INDEX('Tier Calcs'!$A$35:$N$46,T6,U6)} -> 1 | R6: =IF(S_TN_5>0,S_TN_5,9) -> 9 | S6: =_xlfn.IFNA(LOOKUP(P6,$A$3:$C$14,$C$3:$C$14),"") -> 6 | T6: =MATCH(P6,'Tier Calcs'!$A$33:$A$46,0) -> 5 | U6: =MATCH(R6,'Tier Calcs'!$A$33:$N$33,0) -> 11
A7: 5 | B7: 5 | C7: =B7+C6 -> 15 | D7: Proficient | F7: Craft | G7: Mind | O7: 6 | P7: =SR_6 -> 4 | Q7: {=INDEX('Tier Calcs'!$A$35:$N$46,T7,U7)} -> 2 | R7: =IF(S_TN_6>0,S_TN_6,9) -> 9 | S7: =_xlfn.IFNA(LOOKUP(P7,$A$3:$C$14,$C$3:$C$14),"") -> 10 | T7: =MATCH(P7,'Tier Calcs'!$A$33:$A$46,0) -> 6 | U7: =MATCH(R7,'Tier Calcs'!$A$33:$N$33,0) -> 11
A8: 6 | B8: 6 | C8: =B8+C7 -> 21 | D8: Adept | F8: Handling | G8: Mind | O8: 7 | P8: =SR_7 -> 3 | Q8: {=INDEX('Tier Calcs'!$A$35:$N$46,T8,U8)} -> 1 | R8: =IF(S_TN_7>0,S_TN_7,9) -> 9 | S8: =_xlfn.IFNA(LOOKUP(P8,$A$3:$C$14,$C$3:$C$14),"") -> 6 | T8: =MATCH(P8,'Tier Calcs'!$A$33:$A$46,0) -> 5 | U8: =MATCH(R8,'Tier Calcs'!$A$33:$N$33,0) -> 11
A9: 7 | B9: 7 | C9: =B9+C8 -> 28 | D9: Accomplished | F9: Infiltration | G9: Mind | O9: 8 | P9: =SR_8 -> 3 | Q9: {=INDEX('Tier Calcs'!$A$35:$N$46,T9,U9)} -> 2 | R9: =IF(S_TN_8>0,S_TN_8,9) -> 8 | S9: =_xlfn.IFNA(LOOKUP(P9,$A$3:$C$14,$C$3:$C$14),"") -> 6 | T9: =MATCH(P9,'Tier Calcs'!$A$33:$A$46,0) -> 5 | U9: =MATCH(R9,'Tier Calcs'!$A$33:$N$33,0) -> 10
A10: 8 | B10: 8 | C10: =B10+C9 -> 36 | D10: Veteran | F10: Influence | G10: Mind | O10: 9 | P10: =SR_9 -> 3 | Q10: {=INDEX('Tier Calcs'!$A$35:$N$46,T10,U10)} -> 1 | R10: =IF(S_TN_9>0,S_TN_9,9) -> 9 | S10: =_xlfn.IFNA(LOOKUP(P10,$A$3:$C$14,$C$3:$C$14),"") -> 6 | T10: =MATCH(P10,'Tier Calcs'!$A$33:$A$46,0) -> 5 | U10: =MATCH(R10,'Tier Calcs'!$A$33:$N$33,0) -> 11
A11: 9 | B11: 9 | C11: =B11+C10 -> 45 | D11: Expert | F11: Knowledge | G11: Mind | S11: =SUM(S2:S10,V2:V10,W2:W10) -> 136
A12: 10 | B12: 10 | C12: =B12+C11 -> 55 | D12: Master | F12: Language | G12: Mind
A13: 11 | B13: 11 | C13: =B13+C12 -> 66 | D13: Renowned | F13: Performance | G13: Mind
A14: 12 | B14: 12 | C14: =B14+C13 -> 78 | D14: Legendary | F14: Piloting | G14: Mind
F15: Survival | G15: Mind

Sheet Skill Data
A1: Skill Name | B1: Broad | C1: Rank | D1: Techniques | E1: Edges | F1: Target | G1: Damage | H1: Bulk
A2: Engineering, Civil | B2: Knowledge | C2: 6
A3: Mag Vehicles | B3: Piloting | C3: 6 | D3: Stunt Pilot (2:12) | E3: Agile
A4: Tailoring/Weaving | B4: Craft | C4: 6 | E4: Agile | H4: 5
A5: Dueling Weapons | B5: Combat: Melee | C5: 6 | E5: Agile | G5: 2 | H5: 1

Sheet Tier Calcs
A2: Facing | B2: TN 1 | C2: TN 2 | D2: TN 3 | E2: TN 4 | F2: TN 5 | G2: TN 6 | H2: TN 7 | I2: TN 8 | J2: TN 9 | K2: TN 10 | L2: TN 11 | M2: TN 12
A3: 1 | B3: 0
A4: 2 | B4: 0 | C4: 1
A5: 3 | B5: 0 | C5: 1 | D5: 1
A6: 4 | B6: 0 | C6: 1 | D6: 1 | E6: 1
A7: 5 | B7: 0 | C7: 1 | D7: 1 | E7: 1 | F7: 1
A8: 6 | B8: 0 | C8: 1 | D8: 1 | E8: 1 | F8: 1 | G8: 1
A9: 7 | B9: 0 | C9: 1 | D9: 1 | E9: 1 | F9: 1 | G9: 1 | H9: 1
A10: 8 | B10: 0 | C10: 1 | D10: 1 | E10: 1 | F10: 1 | G10: 1 | H10: 1 | I10: 1
A11: 9 | B11: 0 | C11: 1 | D11: 1 | E11: 1 | F11: 1 | G11: 1 | H11: 1 | I11: 1 | J11: 1
A12: 10 | B12: 0 | C12: 1 | D12: 1 | E12: 1 | F12: 1 | G12: 1 | H12: 1 | I12: 1 | J12: 1 | K12: 1
A13: 11 | B13: 0 | C13: 1 | D13: 1 | E13: 1 | F13: 1 | G13: 1 | H13: 1 | I13: 1 | J13: 1 | K13: 1 | L13: 1
A14: 12 | B14: 0 | C14: 1 | D14: 1 | E14: 1 | F14: 1 | G14: 1 | H14: 1 | I14: 1 | J14: 1 | K14: 1 | L14: 1 | M14: 1
B15: =(SUM(B3:B14)/12) -> 0 | C15: =(SUM(C3:C14)/12) -> 0.91666667 | D15: =(SUM(D3:D14)/12) -> 0.83333333 | E15: =(SUM(E3:E14)/12) -> 0.75 | F15: =(SUM(F3:F14)/12) -> 0.66666667 | G15: =(SUM(G3:G14)/12) -> 0.58333333 | H15: =(SUM(H3:H14)/12) -> 0.5 | I15: =(SUM(I3:I14)/12) -> 0.41666667 | ... M15: =(SUM(M3:M14)/12) -> 0.083333333
B17: Number of Dice
A18: TN | B18: 1 | C18: 2 | D18: 3 | E18: 4 | F18: 5 | G18: 6 | H18: 7 | I18: 8 | J18: 9 | K18: 10 | L18: 11 | M18: 12
A19: 1 | B19: =$B$15*B$18 -> 0 | C19: =$B$15*C$18 -> 0 | D19: =$B$15*D$18 -> 0 | E19: =$B$15*E$18 -> 0 | F19: =$B$15*F$18 -> 0 | G19: =$B$15*G$18 -> 0 | H19: =$B$15*H$18 -> 0 | I19: =$B$15*I$18 -> 0 | ... M19: =$B$15*M$18 -> 0
A20: 2 | B20: =$C$15*B$18 -> 0.91666667 | C20: =$C$15*C$18 -> 1.8333333 | D20: =$C$15*D$18 -> 2.75 | E20: =$C$15*E$18 -> 3.6666667 | F20: =$C$15*F$18 -> 4.5833333 | G20: =$C$15*G$18 -> 5.5 | H20: =$C$15*H$18 -> 6.4166667 | I20: =$C$15*I$18 -> 7.3333333 | ... M20: =$C$15*M$18 -> 11
A21: 3 | B21: =$D$15*B$18 -> 0.83333333 | C21: =$D$15*C$18 -> 1.6666667 | D21: =$D$15*D$18 -> 2.5 | E21: =$D$15*E$18 -> 3.3333333 | F21: =$D$15*F$18 -> 4.1666667 | G21: =$D$15*G$18 -> 5 | H21: =$D$15*H$18 -> 5.8333333 | I21: =$D$15*I$18 -> 6.6666667 | ... M21: =$D$15*M$18 -> 10
A22: 4 | B22: =$E$15*B$18 -> 0.75 | C22: =$E$15*C$18 -> 1.5 | D22: =$E$15*D$18 -> 2.25 | E22: =$E$15*E$18 -> 3 | F22: =$E$15*F$18 -> 3.75 | G22: =$E$15*G$18 -> 4.5 | H22: =$E$15*H$18 -> 5.25 | I22: =$E$15*I$18 -> 6 | ... M22: =$E$15*M$18 -> 9
A23: 5 | B23: =$F$15*B$18 -> 0.66666667 | C23: =$F$15*C$18 -> 1.3333333 | D23: =$F$15*D$18 -> 2 | E23: =$F$15*E$18 -> 2.6666667 | F23: =$F$15*F$18 -> 3.3333333 | G23: =$F$15*G$18 -> 4 | H23: =$F$15*H$18 -> 4.6666667 | I23: =$F$15*I$18 -> 5.3333333 | ... M23: =$F$15*M$18 -> 8
A24: 6 | B24: =$G$15*B$18 -> 0.58333333 | C24: =$G$15*C$18 -> 1.1666667 | D24: =$G$15*D$18 -> 1.75 | E24: =$G$15*E$18 -> 2.3333333 | F24: =$G$15*F$18 -> 2.9166667 | G24: =$G$15*G$18 -> 3.5 | H24: =$G$15*H$18 -> 4.0833333 | I24: =$G$15*I$18 -> 4.6666667 | ... M24: =$G$15*M$18 -> 7
A25: 7 | B25: =$H$15*B$18 -> 0.5 | C25: =$H$15*C$18 -> 1 | D25: =$H$15*D$18 -> 1.5 | E25: =$H$15*E$18 -> 2 | F25: =$H$15*F$18 -> 2.5 | G25: =$H$15*G$18 -> 3 | H25: =$H$15*H$18 -> 3.5 | I25: =$H$15*I$18 -> 4 | ... M25: =$H$15*M$18 -> 6
A26: 8 | B26: =$I$15*B$18 -> 0.41666667 | C26: =$I$15*C$18 -> 0.83333333 | D26: =$I$15*D$18 -> 1.25 | E26: =$I$15*E$18 -> 1.6666667 | F26: =$I$15*F$18 -> 2.0833333 | G26: =$I$15*G$18 -> 2.5 | H26: =$I$15*H$18 -> 2.9166667 | I26: =$I$15*I$18 -> 3.3333333 | ... M26: =$I$15*M$18 -> 5
A27: 9 | B27: =$J$15*B$18 -> 0.33333333 | C27: =$J$15*C$18 -> 0.66666667 | D27: =$J$15*D$18 -> 1 | E27: =$J$15*E$18 -> 1.3333333 | F27: =$J$15*F$18 -> 1.6666667 | G27: =$J$15*G$18 -> 2 | H27: =$J$15*H$18 -> 2.3333333 | I27: =$J$15*I$18 -> 2.6666667 | ... M27: =$J$15*M$18 -> 4
A28: 10 | B28: =$K$15*B$18 -> 0.25 | C28: =$K$15*C$18 -> 0.5 | D28: =$K$15*D$18 -> 0.75 | E28: =$K$15*E$18 -> 1 | F28: =$K$15*F$18 -> 1.25 | G28: =$K$15*G$18 -> 1.5 | H28: =$K$15*H$18 -> 1.75 | I28: =$K$15*I$18 -> 2 | ... M28: =$K$15*M$18 -> 3
A29: 11 | B29: =$L$15*B$18 -> 0.16666667 | C29: =$L$15*C$18 -> 0.33333333 | D29: =$L$15*D$18 -> 0.5 | E29: =$L$15*E$18 -> 0.66666667 | F29: =$L$15*F$18 -> 0.83333333 | G29: =$L$15*G$18 -> 1 | H29: =$L$15*H$18 -> 1.1666667 | I29: =$L$15*I$18 -> 1.3333333 | ... M29: =$L$15*M$18 -> 2
A30: 12 | B30: =$M$15*B$18 -> 0.083333333 | C30: =$M$15*C$18 -> 0.16666667 | D30: =$M$15*D$18 -> 0.25 | E30: =$M$15*E$18 -> 0.33333333 | F30: =$M$15*F$18 -> 0.41666667 | G30: =$M$15*G$18 -> 0.5 | H30: =$M$15*H$18 -> 0.58333333 | I30: =$M$15*I$18 -> 0.66666667 | ... M30: =$M$15*M$18 -> 1
A32: Tier | B32: Target Number
A33: S Rank | B33: 0 | C33: 1 | D33: 2 | E33: 3 | F33: 4 | G33: 5 | H33: 6 | I33: 7 | J33: 8 | K33: 9 | L33: 10 | M33: 11 | N33: 12
A34: 0 | B34: 0 | C34: 0 | D34: 0 | E34: 0 | F34: 0 | G34: 0 | H34: 0 | I34: 0 | J34: 0 | K34: 0 | L34: 0 | M34: 0 | N34: 0
A35: 1 | B35: 0 | C35: 0 | D35: 0 | E35: 0 | F35: 0 | G35: 0 | H35: 0 | I35: 0 | J35: 0 | K35: 0 | L35: 0 | M35: 0 | N35: 0
A36: 2 | B36: 0 | C36: 0 | D36: 1 | E36: 1 | F36: 1 | G36: 1 | H36: 1 | I36: 1 | J36: 0 | K36: 0 | L36: 0 | M36: 0 | N36: 0
A37: 3 | B37: 0 | C37: 0 | D37: 2 | E37: 2 | F37: 2 | G37: 2 | H37: 1 | I37: 1 | J37: 1 | K37: 1 | L37: 0 | M37: 0 | N37: 0
A38: 4 | B38: 0 | C38: 0 | D38: 3 | E38: 3 | F38: 3 | G38: 2 | H38: 2 | I38: 2 | J38: 1 | K38: 1 | L38: 1 | M38: 0 | N38: 0
A39: 5 | B39: 0 | C39: 0 | D39: 4 | E39: 4 | F39: 3 | G39: 3 | H39: 2 | I39: 2 | J39: 2 | K39: 1 | L39: 1 | M39: 0 | N39: 0
A40: 6 | B40: 0 | C40: 0 | D40: 5 | E40: 5 | F40: 4 | G40: 4 | H40: 3 | I40: 3 | J40: 2 | K40: 2 | L40: 1 | M40: 1 | N40: 0
A41: 7 | B41: 0 | C41: 0 | D41: 6 | E41: 5 | F41: 5 | G41: 4 | H41: 3 | I41: 3 | J41: 2 | K41: 2 | L41: 1 | M41: 1 | N41: 0
A42: 8 | B42: 0 | C42: 0 | D42: 7 | E42: 6 | F42: 6 | G42: 5 | H42: 4 | I42: 4 | J42: 3 | K42: 2 | L42: 2 | M42: 1 | N42: 0
A43: 9 | B43: 0 | C43: 0 | D43: 8 | E43: 7 | F43: 6 | G43: 6 | H43: 4 | I43: 4 | J43: 3 | K43: 3 | L43: 2 | M43: 1 | N43: 0
...

Sheet Parameters
A1: Cost | B1: Range & Area (Assign Cost Twice) | K1: Potency | Q1: x 1 | R1: x 2 | S1: x 3 | T1: x 4 | U1: x 5 | V1: x 6 | W1: x 7
A2: 0 | B2: Target | C2: self or target | K2: Cost | L2: TN | M2: DL/Reroll | N2: Base | P2: 3 | Q2: 3 | R2: - | S2: 8 | T2: -
A3: 1 | B3: Engaged | C3: within reach | K3: 0 | L3: - | M3: - | N3: - | P3: 4 | Q3: 4 | R3: 5 | S3: - | T3: 13
A4: 2 | B4: Close | C4: Those you could speak with without shouting in a restaurant | K4: 1 | L4: - | M4: - | N4: 1 | P4: 5 | Q4: 5 | R4: - | S4: - | T4: -
A5: 3 | B5: Short | C5: Those you could play catch with or speak with if you raised your voice | K5: 2 | L5: - | M5: 1 | N5: 2 | P5: 6 | Q5: 6 | R5: 6 | S5: 9 | T5: -
A6: 4 | B6: Near | C6: With Speaker and Microphone they could hear you | K6: 3 | L6: 1 | M6: - | N6: 3 | P6: 7 | Q6: 7 | R6: - | S6: - | T6: -
A7: 5 | B7: Apart | C7: You could see them unaided if you had 20/20 vision. | K7: 4 | L7: - | M7: 2 | N7: 4 | P7: 8 | Q7: 8 | R7: 7 | S7: - | T7: 14
A8: =A7*2 -> 10 | B8: Distant | C8: You could walk there in less than an hour | K8: 5 | L8: - | M8: - | N8: 5 | P8: 9 | Q8: 9 | R8: - | S8: 10 | T8: -
A9: =A8*2 -> 20 | B9: City | C9: You could walk there in a day | K9: 6 | L9: 2 | M9: 3 | N9: 6 | P9: 10 | Q9: 10 | R9: 8 | S9: - | T9: -
A10: =A9*2 -> 40 | B10: Vast | C10: It would take you several days to walk there. | K10: 7 | L10: - | M10: - | N10: 7 | P10: 11 | Q10: 11 | R10: - | S10: - | T10: -
A11: =A10*2 -> 80 | B11: Continent | C11: Landmass away, an epic walk | K11: 8 | L11: - | M11: 4 | N11: 8 | P11: 12 | Q11: 12 | R11: 9 | S11: 11 | T11: 15
A12: =A11*2 -> 160 | B12: World | C12: The entire world contained within a Magnetic Field | K12: 9 | L12: 3 | M12: - | N12: 9 | P12: 13 | R12: - | S12: - | T12: -
A13: =A12*2 -> 320 | B13: System | C13: The entire Solar System contained by the Heliosphere of the Sun(s) | K13: 10 | L13: - | M13: 5 | N13: 10 | P13: 14 | R13: 10 | S13: - | T13: -
A14: =A13*2 -> 640 | B14: Beyond | C14: Pretty much any distance, recommend that it isn't the entire galaxy. | K14: 11 | L14: - | M14: - | N14: 11 | P14: 15 | R14: - | S14: 12 | T14: -
K15: 12 | L15: 4 | M15: 6 | N15: 12 | P15: 16 | R15: 11 | S15: - | T15: 16
A16: Cost | B16: Durations | P16: 17 | R16: - | S16: - | T16: -
A17: 0 | B17: Instant | C17: a heartbeat | P17: 18 | R17: 12 | S17: 13 | T17: -
A18: 1 | B18: 3 | C18: 3 rounds | P18: 19 | R18: - | S18: - | T18: -
A19: 2 | B19: 6 | C19: 6 rounds | P19: 20 | R19: 13 | S19: - | T19: 17
A20: 3 | B20: Turn | C20: a spirited exchange between two arguing | P20: 21 | R20: - | S20: 14 | T20: -
A21: 4 | B21: Scene | C21: the entire argument | P21: 22 | R21: 14 | S21: - | T21: -
A22: 6 | B22: Day | C22: the turning of a planet | P22: 23 | R22: - | S22: - | T22: -
A23: 12 | B23: Week | C23: a grouping of days, determined by a calendar | P23: 24 | R23: 15 | S23: 15 | T23: 18
A24: 24 | B24: Month | C24: the complete cycle of a astral body | P24: 25 | S24: - | T24: -
A25: 48 | B25: Season | C25: Solstice to Equinox or vice versa | P25: 26 | S25: - | T25: -
A26: 96 | B26: Year | C26: the rotation of the planet around a sun | P26: 27 | S26: 16 | T26: -
A27: 192 | B27: Decade | C27: 10 rotations | P27: 28 | S27: - | T27: 19
A28: 384 | B28: Lifetime | C28: the lifetime of the target | P28: 29 | S28: - | T28: -
A29: 768 | B29: Permanent | C29: incalculable duration | P29: 30 | S29: 17 | T29: -
P30: 31 | S30: - | T30: -
P31: 32 | S31: - | T31: 20
P32: 33 | S32: 18 | T32: -
P33: 34 | S33: - | T33: -
P34: 35 | S34: - | T34: -
P35: 36 | S35: 19 | T35: 21
P36: 37 | T36: -
P37: 38 | T37: -
P38: 39 | T38: -
P39: 40 | T39: 22
P40: 41 | T40: -
...

Sheet Rules
A1: Moral Code
A2: Conducts | V2: In Tribe | AA2: Out of Tribe | AF2: Cost
A3: Killing | V3: 3 | AA3: 2 | AF3: 0
A5: Lying | V5: 1 | AA5: 0 | AF5: 0
A7: Breaking Word | V7: 4 | AA7: 3 | AF7: 0
A9: Stealing | V9: 2 | AA9: 1 | AF9: 0
A11: Denying Aid | V11: 2 | AA11: 0 | AF11: 0
